Workbook
Name Contas: 'Plano de Contas'!$B$4:$B$52
Name Documentos: 'Plano de Contas'!$E$4:$E$9

Sheet Plano de Contas
A2: Plano de Contas
B4: Contas | C4: Descrição | E4: Documentos
B5: RECEITAS OPERACIONAIS | C5: Receitas derivadas da atividade principal da empresa | E5: Cartão de crédito
B6: Consultoria | C6: Receita advinda da atividade de consultoria em sistemas de informação | E6: Cobrança bancária
B7: Licença de software | C7: Receita de venda de sistemas e/ou licença de sistemas | E7: Cheque
B8: Manutenção de estrutura | C8: Receita advinda de contratos de manutenção em estrutura de tecnologia | E8: Deposito bancário
B9: Manutenção de Sistemas | C9: Receitas advindas das manutenções dos sistemas desenvolvidos pela empresa | E9: Dinheiro
B10: Outras receitas | C10: Outras receitas não especificadas
B11: DESPESAS FIXAS | C11: Despesas de natureza operacional e não relacionadas ao volume de atividade
B12: Água | C12: Despesas de água encanada e água mineral
B13: Aluguel | C13: Aluguel do prédio
B14: Cartório | C14: Despesas de cartório
B15: Combustível | C15: Despesas de combustível dos veículos
B16: Correios | C16: Despesas de envio de cartas, mala direta e sedex
B17: Encargos sociais | C17: Despesas de encargos sociais sobre a folha, seguro de vida e plano de saúde
B18: Energia | C18: Energia elétrica
B19: Fones / Comunicação | C19: Despesas de telefones fixo e móvel e internet
B20: Impostos/taxas diversas | C20: Impostos e taxas diversas, tais como IPTU, IPVA, CPMF, taxas de conselhos e sindicatos, taxas de concorrências públicas, etc.
B21: Manutenção equipamentos | C21: Manutenção de computadores, impressoras, TVs, circuito de TV, copiadora, etc.
... B52: Pgto. empréstimo (juros) | C52: Pagamento de empréstimos contraídos (juros)

Sheet Premissas
A2: Premissas
B4: Ano de avaliação | C4: =TEXT(TODAY(),"aaaa") -> 2020
B5: Saldo Inicial | C5: 0
B7: Faturamento Projetado
B8: Contas | C8: Jan | D8: Fev | E8: Mar | F8: Abr | G8: Mai | H8: Jun | I8: Jul | J8: Ago | K8: Set | L8: Out | M8: Nov | N8: Dez
B9: ='Plano de Contas'!B6 -> Consultoria | C9: 10253 | D9: 10041 | E9: 10342 | F9: 11842 | G9: 11449 | H9: 10189 | I9: 11481 | J9: 11464 | K9: 11205 | L9: 10930 | M9: 11763 | N9: 11251
B10: ='Plano de Contas'!B7 -> Licença de software | C10: 10358 | D10: 10263 | E10: 10055 | F10: 10745 | G10: 10725 | H10: 11887 | I10: 11547 | J10: 10194 | K10: 11618 | L10: 10717 | M10: 10787 | N10: 10904
B11: ='Plano de Contas'!B8 -> Manutenção de estrutura | C11: 5515 | D11: 5379 | E11: 5788 | F11: 4634 | G11: 5447 | H11: 4672 | I11: 5532 | J11: 5451 | K11: 4727 | L11: 5029 | M11: 4485 | N11: 4080
B12: ='Plano de Contas'!B9 -> Manutenção de Sistemas | C12: 1618 | D12: 1998 | E12: 1997 | F12: 1521 | G12: 1551 | H12: 1326 | I12: 1451 | J12: 1611 | K12: 1658 | L12: 1030 | M12: 1165 | N12: 1101
B13: ='Plano de Contas'!B10 -> Outras receitas | C13: 933 | D13: 965 | E13: 886 | F13: 930 | G13: 901 | H13: 897 | I13: 892 | J13: 987 | K13: 978 | L13: 890 | M13: 806 | N13: 922
B15: Total | C15: =SUM(C9:C13) -> 28677 | D15: =SUM(D9:D13) -> 28646 | E15: =SUM(E9:E13) -> 29068 | F15: =SUM(F9:F13) -> 29672 | G15: =SUM(G9:G13) -> 30073 | H15: =SUM(H9:H13) -> 28971 | I15: =SUM(I9:I13) -> 30903 | J15: =SUM(J9:J13) -> 29707 | ... N15: =SUM(N9:N13) -> 28258
B17: Despesas Fixas Mensais
B18: ='Plano de Contas'!B12 -> Água | C18: 90
B19: ='Plano de Contas'!B13 -> Aluguel | C19: 500
B20: ='Plano de Contas'!B14 -> Cartório | C20: 150
B21: ='Plano de Contas'!B15 -> Combustível | C21: 500
B22: ='Plano de Contas'!B16 -> Correios | C22: 150
B23: ='Plano de Contas'!B17 -> Encargos sociais | C23: 4000
B24: ='Plano de Contas'!B18 -> Energia | C24: 1200
B25: ='Plano de Contas'!B19 -> Fones / Comunicação | C25: 200
B26: ='Plano de Contas'!B20 -> Impostos/taxas diversas | C26: 1000
B27: ='Plano de Contas'!B21 -> Manutenção equipamentos | C27: 600
B28: ='Plano de Contas'!B22 -> Manutenção prédio | C28: 600
B29: ='Plano de Contas'!B23 -> Material escritório | C29: 246
... B38: ='Plano de Contas'!B32 -> Viagens | C38: 208
B40: Despesas Variáveis
B41: ='Plano de Contas'!B34 -> Comissões | C41: 0.05 | D41: Pago em M sobre o faturamento
B42: ='Plano de Contas'!B35 -> Impostos estaduais | C42: 0 | D42: Não tem comercialização de produtos
B43: ='Plano de Contas'!B36 -> Impostos federais | C43: 0.1133 | D43: Pago em M+1 sobre faturamento. PIS 0,65%, Confins 3%, Cont. Social 2,88%, IRPJ 4,8%
B44: ='Plano de Contas'!B37 -> Impostos municipais | C44: 0.05 | D44: Pago em M+1 sobre faturamento. ISS 5,00%
B45: ='Plano de Contas'!B38 -> Outras despesas variáveis | C45: 0

Sheet Receitas
A2: Receitas
C4: Regras de Faturamento
B5: Serviços | C5: À Vista | D5: 30 dias
B6: ='Plano de Contas'!B6 -> Consultoria | C6: 0.5 | D6: 0.5
B7: ='Plano de Contas'!B7 -> Licença de software | C7: 0.5 | D7: 0.5
B8: ='Plano de Contas'!B8 -> Manutenção de estrutura | C8: 0.25 | D8: 0.75
B9: ='Plano de Contas'!B9 -> Manutenção de Sistemas | D9: 1
B10: ='Plano de Contas'!B10 -> Outras receitas | D10: 1
B12: Faturamento Projetado
C13: =Premissas!C8 -> Jan | D13: =Premissas!D8 -> Fev | E13: =Premissas!E8 -> Mar | F13: =Premissas!F8 -> Abr | G13: =Premissas!G8 -> Mai | H13: =Premissas!H8 -> Jun | I13: =Premissas!I8 -> Jul | J13: =Premissas!J8 -> Ago | ... N13: =Premissas!N8 -> Dez
B14: =Premissas!B9 -> Consultoria | C14: =Premissas!C9 -> 10253 | D14: =Premissas!D9 -> 10041 | E14: =Premissas!E9 -> 10342 | F14: =Premissas!F9 -> 11842 | G14: =Premissas!G9 -> 11449 | H14: =Premissas!H9 -> 10189 | I14: =Premissas!I9 -> 11481 | ... N14: =Premissas!N9 -> 11251
B15: =Premissas!B10 -> Licença de software | C15: =Premissas!C10 -> 10358 | D15: =Premissas!D10 -> 10263 | E15: =Premissas!E10 -> 10055 | F15: =Premissas!F10 -> 10745 | G15: =Premissas!G10 -> 10725 | H15: =Premissas!H10 -> 11887 | I15: =Premissas!I10 -> 11547 | ... N15: =Premissas!N10 -> 10904
B16: =Premissas!B11 -> Manutenção de estrutura | C16: =Premissas!C11 -> 5515 | D16: =Premissas!D11 -> 5379 | E16: =Premissas!E11 -> 5788 | F16: =Premissas!F11 -> 4634 | G16: =Premissas!G11 -> 5447 | H16: =Premissas!H11 -> 4672 | I16: =Premissas!I11 -> 5532 | ... N16: =Premissas!N11 -> 4080
B17: =Premissas!B12 -> Manutenção de Sistemas | C17: =Premissas!C12 -> 1618 | D17: =Premissas!D12 -> 1998 | E17: =Premissas!E12 -> 1997 | F17: =Premissas!F12 -> 1521 | G17: =Premissas!G12 -> 1551 | H17: =Premissas!H12 -> 1326 | I17: =Premissas!I12 -> 1451 | ... N17: =Premissas!N12 -> 1101
B18: =Premissas!B13 -> Outras receitas | C18: =Premissas!C13 -> 933 | D18: =Premissas!D13 -> 965 | E18: =Premissas!E13 -> 886 | F18: =Premissas!F13 -> 930 | G18: =Premissas!G13 -> 901 | H18: =Premissas!H13 -> 897 | I18: =Premissas!I13 -> 892 | ... N18: =Premissas!N13 -> 922
B19: Total | C19: =SUM(C14:C18) -> 28677 | D19: =SUM(D14:D18) -> 28646 | E19: =SUM(E14:E18) -> 29068 | F19: =SUM(F14:F18) -> 29672 | G19: =SUM(G14:G18) -> 30073 | H19: =SUM(H14:H18) -> 28971 | I19: =SUM(I14:I18) -> 30903 | J19: =SUM(J14:J18) -> 29707 | ... N19: =SUM(N14:N18) -> 28258 | R19: =SUM(C19:Q19) -> 351763
B22: Receita Projetada
C23: =C13 -> Jan | D23: =D13 -> Fev | E23: =E13 -> Mar | F23: =F13 -> Abr | G23: =G13 -> Mai | H23: =H13 -> Jun | I23: =I13 -> Jul | J23: =J13 -> Ago | ... N23: =N13 -> Dez | O23: Jan
B24: =B14 -> Consultoria | C24: =C14*C6 -> 5126.5 | D24: =(D14*$C6)+(C14*$D6) -> 10147 | E24: =(E14*$C6)+(D14*$D6) -> 10191.5 | F24: =(F14*$C6)+(E14*$D6) -> 11092 | G24: =(G14*$C6)+(F14*$D6) -> 11645.5 | H24: =(H14*$C6)+(G14*$D6) -> 10819 | I24: =(I14*$C6)+(H14*$D6) -> 10835 | J24: =(J14*$C6)+(I14*$D6) -> 11472.5 | K24: =(K14*$C6)+(J14*$D6) -> 11334.5 | ... O24: =(O14*$C6)+(N14*$D6) -> 5625.5
B25: =B15 -> Licença de software | C25: =C15*C7 -> 5179 | D25: =(D15*$C7)+(C15*$D7) -> 10310.5 | E25: =(E15*$C7)+(D15*$D7) -> 10159 | F25: =(F15*$C7)+(E15*$D7) -> 10400 | G25: =(G15*$C7)+(F15*$D7) -> 10735 | H25: =(H15*$C7)+(G15*$D7) -> 11306 | I25: =(I15*$C7)+(H15*$D7) -> 11717 | J25: =(J15*$C7)+(I15*$D7) -> 10870.5 | K25: =(K15*$C7)+(J15*$D7) -> 10906 | ... O25: =(O15*$C7)+(N15*$D7) -> 5452
B26: =B16 -> Manutenção de estrutura | C26: =C16*C8 -> 1378.75 | D26: =(D16*$C8)+(C16*$D8) -> 5481 | E26: =(E16*$C8)+(D16*$D8) -> 5481.25 | F26: =(F16*$C8)+(E16*$D8) -> 5499.5 | G26: =(G16*$C8)+(F16*$D8) -> 4837.25 | H26: =(H16*$C8)+(G16*$D8) -> 5253.25 | I26: =(I16*$C8)+(H16*$D8) -> 4887 | J26: =(J16*$C8)+(I16*$D8) -> 5511.75 | K26: =(K16*$C8)+(J16*$D8) -> 5270 | ... O26: =(O16*$C8)+(N16*$D8) -> 3060
B27: =B17 -> Manutenção de Sistemas | C27: =C17*C9 -> 0 | D27: =(D17*$C9)+(C17*$D9) -> 1618 | E27: =(E17*$C9)+(D17*$D9) -> 1998 | F27: =(F17*$C9)+(E17*$D9) -> 1997 | G27: =(G17*$C9)+(F17*$D9) -> 1521 | H27: =(H17*$C9)+(G17*$D9) -> 1551 | I27: =(I17*$C9)+(H17*$D9) -> 1326 | J27: =(J17*$C9)+(I17*$D9) -> 1451 | K27: =(K17*$C9)+(J17*$D9) -> 1611 | ... O27: =(O17*$C9)+(N17*$D9) -> 1101
B28: =B18 -> Outras receitas | C28: =C18*C10 -> 0 | D28: =(D18*$C10)+(C18*$D10) -> 933 | E28: =(E18*$C10)+(D18*$D10) -> 965 | F28: =(F18*$C10)+(E18*$D10) -> 886 | G28: =(G18*$C10)+(F18*$D10) -> 930 | H28: =(H18*$C10)+(G18*$D10) -> 901 | I28: =(I18*$C10)+(H18*$D10) -> 897 | J28: =(J18*$C10)+(I18*$D10) -> 892 | K28: =(K18*$C10)+(J18*$D10) -> 987 | ... O28: =(O18*$C10)+(N18*$D10) -> 922
B29: Total | C29: =SUM(C24:C28) -> 11684.25 | D29: =SUM(D24:D28) -> 28489.5 | E29: =SUM(E24:E28) -> 28794.75 | F29: =SUM(F24:F28) -> 29874.5 | G29: =SUM(G24:G28) -> 29668.75 | H29: =SUM(H24:H28) -> 29830.25 | I29: =SUM(I24:I28) -> 29662 | J29: =SUM(J24:J28) -> 30197.75 | ... O29: =SUM(O24:O28) -> 16160.5 | R29: =SUM(C29:N29) -> 335602.5

Sheet Fluxo_Projetado
A2: ="Fluxo de Caixa Projetado - "&Premissas!C4 -> Fluxo de Caixa Projetado - 2020
B4: Contas | C4: Jan | D4: Fev | E4: Mar | F4: Abr | G4: Mai | H4: Jun | I4: Jul | J4: Ago | K4: Set | L4: Out | M4: Nov | N4: Dez | O4: Jan | P4: Total | Q4: Média
B5: ='Plano de Contas'!B5 -> RECEITAS OPERACIONAIS | C5: =SUM(C6:C10) -> 11684.25 | D5: =SUM(D6:D10) -> 28489.5 | E5: =SUM(E6:E10) -> 28794.75 | F5: =SUM(F6:F10) -> 29874.5 | G5: =SUM(G6:G10) -> 29668.75 | H5: =SUM(H6:H10) -> 29830.25 | I5: =SUM(I6:I10) -> 29662 | J5: =SUM(J6:J10) -> 30197.75 | ... O5: =SUM(O6:O10) -> 16160.5 | P5: =SUM(C5:O5) -> 351763 | Q5: =IF(P5=0,0,AVERAGE(C5:O5)) -> 27058.692
B6: ='Plano de Contas'!B6 -> Consultoria | C6: =Receitas!C24 -> 5126.5 | D6: =Receitas!D24 -> 10147 | E6: =Receitas!E24 -> 10191.5 | F6: =Receitas!F24 -> 11092 | G6: =Receitas!G24 -> 11645.5 | H6: =Receitas!H24 -> 10819 | I6: =Receitas!I24 -> 10835 | J6: =Receitas!J24 -> 11472.5 | ... O6: =Receitas!O24 -> 5625.5 | P6: =SUM(C6:O6) -> 132210 | Q6: =IF(P6=0,0,AVERAGE(C6:O6)) -> 10170
B7: ='Plano de Contas'!B7 -> Licença de software | C7: =Receitas!C25 -> 5179 | D7: =Receitas!D25 -> 10310.5 | E7: =Receitas!E25 -> 10159 | F7: =Receitas!F25 -> 10400 | G7: =Receitas!G25 -> 10735 | H7: =Receitas!H25 -> 11306 | I7: =Receitas!I25 -> 11717 | J7: =Receitas!J25 -> 10870.5 | ... O7: =Receitas!O25 -> 5452 | P7: =SUM(C7:O7) -> 129800 | Q7: =IF(P7=0,0,AVERAGE(C7:O7)) -> 9984.6154
B8: ='Plano de Contas'!B8 -> Manutenção de estrutura | C8: =Receitas!C26 -> 1378.75 | D8: =Receitas!D26 -> 5481 | E8: =Receitas!E26 -> 5481.25 | F8: =Receitas!F26 -> 5499.5 | G8: =Receitas!G26 -> 4837.25 | H8: =Receitas!H26 -> 5253.25 | I8: =Receitas!I26 -> 4887 | J8: =Receitas!J26 -> 5511.75 | ... O8: =Receitas!O26 -> 3060 | P8: =SUM(C8:O8) -> 60739 | Q8: =IF(P8=0,0,AVERAGE(C8:O8)) -> 4672.2308
B9: ='Plano de Contas'!B9 -> Manutenção de Sistemas | C9: =Receitas!C27 -> 0 | D9: =Receitas!D27 -> 1618 | E9: =Receitas!E27 -> 1998 | F9: =Receitas!F27 -> 1997 | G9: =Receitas!G27 -> 1521 | H9: =Receitas!H27 -> 1551 | I9: =Receitas!I27 -> 1326 | J9: =Receitas!J27 -> 1451 | ... O9: =Receitas!O27 -> 1101 | P9: =SUM(C9:O9) -> 18027 | Q9: =IF(P9=0,0,AVERAGE(C9:O9)) -> 1386.6923
B10: ='Plano de Contas'!B10 -> Outras receitas | C10: =Receitas!C28 -> 0 | D10: =Receitas!D28 -> 933 | E10: =Receitas!E28 -> 965 | F10: =Receitas!F28 -> 886 | G10: =Receitas!G28 -> 930 | H10: =Receitas!H28 -> 901 | I10: =Receitas!I28 -> 897 | J10: =Receitas!J28 -> 892 | ... O10: =Receitas!O28 -> 922 | P10: =SUM(C10:O10) -> 10987 | Q10: =IF(P10=0,0,AVERAGE(C10:O10)) -> 845.15385
B11: ='Plano de Contas'!B11 -> DESPESAS FIXAS | C11: =SUM(C12:C32) -> -11190 | D11: =SUM(D12:D32) -> -11190 | E11: =SUM(E12:E32) -> -11190 | F11: =SUM(F12:F32) -> -11190 | G11: =SUM(G12:G32) -> -11190 | H11: =SUM(H12:H32) -> -11190 | I11: =SUM(I12:I32) -> -11190 | J11: =SUM(J12:J32) -> -11190 | ... O11: =SUM(O12:O32) -> -11190 | P11: =SUM(C11:O11) -> -145470 | Q11: =IF(P11=0,0,AVERAGE(C11:O11)) -> -11190
B12: ='Plano de Contas'!B12 -> Água | C12: =-Premissas!$C18 -> -90 | D12: =-Premissas!$C18 -> -90 | E12: =-Premissas!$C18 -> -90 | F12: =-Premissas!$C18 -> -90 | G12: =-Premissas!$C18 -> -90 | H12: =-Premissas!$C18 -> -90 | I12: =-Premissas!$C18 -> -90 | J12: =-Premissas!$C18 -> -90 | ... O12: =-Premissas!$C18 -> -90 | P12: =SUM(C12:O12) -> -1170 | Q12: =IF(P12=0,0,AVERAGE(C12:O12)) -> -90
B13: ='Plano de Contas'!B13 -> Aluguel | C13: =-Premissas!$C19 -> -500 | D13: =-Premissas!$C19 -> -500 | E13: =-Premissas!$C19 -> -500 | F13: =-Premissas!$C19 -> -500 | G13: =-Premissas!$C19 -> -500 | H13: =-Premissas!$C19 -> -500 | I13: =-Premissas!$C19 -> -500 | J13: =-Premissas!$C19 -> -500 | ... O13: =-Premissas!$C19 -> -500 | P13: =SUM(C13:O13) -> -6500 | Q13: =IF(P13=0,0,AVERAGE(C13:O13)) -> -500
B14: ='Plano de Contas'!B14 -> Cartório | C14: =-Premissas!$C20 -> -150 | D14: =-Premissas!$C20 -> -150 | E14: =-Premissas!$C20 -> -150 | F14: =-Premissas!$C20 -> -150 | G14: =-Premissas!$C20 -> -150 | H14: =-Premissas!$C20 -> -150 | I14: =-Premissas!$C20 -> -150 | J14: =-Premissas!$C20 -> -150 | ... O14: =-Premissas!$C20 -> -150 | P14: =SUM(C14:O14) -> -1950 | Q14: =IF(P14=0,0,AVERAGE(C14:O14)) -> -150
B15: ='Plano de Contas'!B15 -> Combustível | C15: =-Premissas!$C21 -> -500 | D15: =-Premissas!$C21 -> -500 | E15: =-Premissas!$C21 -> -500 | F15: =-Premissas!$C21 -> -500 | G15: =-Premissas!$C21 -> -500 | H15: =-Premissas!$C21 -> -500 | I15: =-Premissas!$C21 -> -500 | J15: =-Premissas!$C21 -> -500 | ... O15: =-Premissas!$C21 -> -500 | P15: =SUM(C15:O15) -> -6500 | Q15: =IF(P15=0,0,AVERAGE(C15:O15)) -> -500
B16: ='Plano de Contas'!B16 -> Correios | C16: =-Premissas!$C22 -> -150 | D16: =-Premissas!$C22 -> -150 | E16: =-Premissas!$C22 -> -150 | F16: =-Premissas!$C22 -> -150 | G16: =-Premissas!$C22 -> -150 | H16: =-Premissas!$C22 -> -150 | I16: =-Premissas!$C22 -> -150 | J16: =-Premissas!$C22 -> -150 | ... O16: =-Premissas!$C22 -> -150 | P16: =SUM(C16:O16) -> -1950 | Q16: =IF(P16=0,0,AVERAGE(C16:O16)) -> -150
B17: ='Plano de Contas'!B17 -> Encargos sociais | C17: =-Premissas!$C23 -> -4000 | D17: =-Premissas!$C23 -> -4000 | E17: =-Premissas!$C23 -> -4000 | F17: =-Premissas!$C23 -> -4000 | G17: =-Premissas!$C23 -> -4000 | H17: =-Premissas!$C23 -> -4000 | I17: =-Premissas!$C23 -> -4000 | J17: =-Premissas!$C23 -> -4000 | ... O17: =-Premissas!$C23 -> -4000 | P17: =SUM(C17:O17) -> -52000 | Q17: =IF(P17=0,0,AVERAGE(C17:O17)) -> -4000
B18: ='Plano de Contas'!B18 -> Energia | C18: =-Premissas!$C24 -> -1200 | D18: =-Premissas!$C24 -> -1200 | E18: =-Premissas!$C24 -> -1200 | F18: =-Premissas!$C24 -> -1200 | G18: =-Premissas!$C24 -> -1200 | H18: =-Premissas!$C24 -> -1200 | I18: =-Premissas!$C24 -> -1200 | J18: =-Premissas!$C24 -> -1200 | ... O18: =-Premissas!$C24 -> -1200 | P18: =SUM(C18:O18) -> -15600 | Q18: =IF(P18=0,0,AVERAGE(C18:O18)) -> -1200
B19: ='Plano de Contas'!B19 -> Fones / Comunicação | C19: =-Premissas!$C25 -> -200 | D19: =-Premissas!$C25 -> -200 | E19: =-Premissas!$C25 -> -200 | F19: =-Premissas!$C25 -> -200 | G19: =-Premissas!$C25 -> -200 | H19: =-Premissas!$C25 -> -200 | I19: =-Premissas!$C25 -> -200 | J19: =-Premissas!$C25 -> -200 | ... O19: =-Premissas!$C25 -> -200 | P19: =SUM(C19:O19) -> -2600 | Q19: =IF(P19=0,0,AVERAGE(C19:O19)) -> -200
B20: ='Plano de Contas'!B20 -> Impostos/taxas diversas | C20: =-Premissas!$C26 -> -1000 | D20: =-Premissas!$C26 -> -1000 | E20: =-Premissas!$C26 -> -1000 | F20: =-Premissas!$C26 -> -1000 | G20: =-Premissas!$C26 -> -1000 | H20: =-Premissas!$C26 -> -1000 | I20: =-Premissas!$C26 -> -1000 | J20: =-Premissas!$C26 -> -1000 | ... O20: =-Premissas!$C26 -> -1000 | P20: =SUM(C20:O20) -> -13000 | Q20: =IF(P20=0,0,AVERAGE(C20:O20)) -> -1000
B21: ='Plano de Contas'!B21 -> Manutenção equipamentos | C21: =-Premissas!$C27 -> -600 | D21: =-Premissas!$C27 -> -600 | E21: =-Premissas!$C27 -> -600 | F21: =-Premissas!$C27 -> -600 | G21: =-Premissas!$C27 -> -600 | H21: =-Premissas!$C27 -> -600 | I21: =-Premissas!$C27 -> -600 | J21: =-Premissas!$C27 -> -600 | ... O21: =-Premissas!$C27 -> -600 | P21: =SUM(C21:O21) -> -7800 | Q21: =IF(P21=0,0,AVERAGE(C21:O21)) -> -600
B22: ='Plano de Contas'!B22 -> Manutenção prédio | C22: =-Premissas!$C28 -> -600 | D22: =-Premissas!$C28 -> -600 | E22: =-Premissas!$C28 -> -600 | F22: =-Premissas!$C28 -> -600 | G22: =-Premissas!$C28 -> -600 | H22: =-Premissas!$C28 -> -600 | I22: =-Premissas!$C28 -> -600 | J22: =-Premissas!$C28 -> -600 | ... O22: =-Premissas!$C28 -> -600 | P22: =SUM(C22:O22) -> -7800 | Q22: =IF(P22=0,0,AVERAGE(C22:O22)) -> -600
B23: ='Plano de Contas'!B23 -> Material escritório | C23: =-Premissas!$C29 -> -246 | D23: =-Premissas!$C29 -> -246 | E23: =-Premissas!$C29 -> -246 | F23: =-Premissas!$C29 -> -246 | G23: =-Premissas!$C29 -> -246 | H23: =-Premissas!$C29 -> -246 | I23: =-Premissas!$C29 -> -246 | J23: =-Premissas!$C29 -> -246 | ... O23: =-Premissas!$C29 -> -246 | P23: =SUM(C23:O23) -> -3198 | Q23: =IF(P23=0,0,AVERAGE(C23:O23)) -> -246
... B32: ='Plano de Contas'!B32 -> Viagens | C32: =-Premissas!$C38 -> -208 | D32: =-Premissas!$C38 -> -208 | E32: =-Premissas!$C38 -> -208 | F32: =-Premissas!$C38 -> -208 | G32: =-Premissas!$C38 -> -208 | H32: =-Premissas!$C38 -> -208 | I32: =-Premissas!$C38 -> -208 | J32: =-Premissas!$C38 -> -208 | ... O32: =-Premissas!$C38 -> -208 | P32: =SUM(C32:O32) -> -2704 | Q32: =IF(P32=0,0,AVERAGE(C32:O32)) -> -208
B33: ='Plano de Contas'!B33 -> DESPESAS VARIÁVEIS | C33: =SUM(C34:C38) -> -1433.85 | D33: =SUM(D34:D38) -> -6115.2541 | E33: =SUM(E34:E38) -> -6131.2918 | F33: =SUM(F34:F38) -> -6230.4044 | G33: =SUM(G34:G38) -> -6349.0876 | H33: =SUM(H34:H38) -> -6359.4709 | I33: =SUM(I34:I38) -> -6276.1143 | J33: =SUM(J34:J38) -> -6531.8099 | ... O33: =SUM(O34:O38) -> -4614.5314 | P33: =SUM(C33:O33) -> -75031.048 | Q33: =IF(P33=0,0,AVERAGE(C33:O33)) -> -5771.6191
B34: ='Plano de Contas'!B34 -> Comissões | C34: =-Premissas!$C$41*Premissas!C15 -> -1433.85 | D34: =-Premissas!$C$41*Premissas!D15 -> -1432.3 | E34: =-Premissas!$C$41*Premissas!E15 -> -1453.4 | F34: =-Premissas!$C$41*Premissas!F15 -> -1483.6 | G34: =-Premissas!$C$41*Premissas!G15 -> -1503.65 | H34: =-Premissas!$C$41*Premissas!H15 -> -1448.55 | I34: =-Premissas!$C$41*Premissas!I15 -> -1545.15 | J34: =-Premissas!$C$41*Premissas!J15 -> -1485.35 | ... O34: =-Premissas!$C$41*Premissas!O15 -> 0 | P34: =SUM(C34:O34) -> -17588.15 | Q34: =IF(P34=0,0,AVERAGE(C34:O34)) -> -1352.9346
B35: ='Plano de Contas'!B35 -> Impostos estaduais | C35: 0 | D35: 0 | E35: 0 | F35: 0 | G35: 0 | H35: 0 | I35: 0 | J35: 0 | K35: 0 | L35: 0 | M35: 0 | N35: 0 | O35: 0 | P35: =SUM(C35:O35) -> 0 | Q35: =IF(P35=0,0,AVERAGE(C35:O35)) -> 0
B36: ='Plano de Contas'!B36 -> Impostos federais | C36: 0 | D36: =-Premissas!$C$43*Premissas!C15 -> -3249.1041 | E36: =-Premissas!$C$43*Premissas!D15 -> -3245.5918 | F36: =-Premissas!$C$43*Premissas!E15 -> -3293.4044 | G36: =-Premissas!$C$43*Premissas!F15 -> -3361.8376 | H36: =-Premissas!$C$43*Premissas!G15 -> -3407.2709 | I36: =-Premissas!$C$43*Premissas!H15 -> -3282.4143 | J36: =-Premissas!$C$43*Premissas!I15 -> -3501.3099 | K36: =-Premissas!$C$43*Premissas!J15 -> -3365.8031 | ... O36: =-Premissas!$C$43*Premissas!N15 -> -3201.6314 | P36: =SUM(C36:O36) -> -39854.748 | Q36: =IF(P36=0,0,AVERAGE(C36:O36)) -> -3065.7498
B37: ='Plano de Contas'!B37 -> Impostos municipais | C37: 0 | D37: =-Premissas!$C$44*Premissas!C15 -> -1433.85 | E37: =-Premissas!$C$44*Premissas!D15 -> -1432.3 | F37: =-Premissas!$C$44*Premissas!E15 -> -1453.4 | G37: =-Premissas!$C$44*Premissas!F15 -> -1483.6 | H37: =-Premissas!$C$44*Premissas!G15 -> -1503.65 | I37: =-Premissas!$C$44*Premissas!H15 -> -1448.55 | J37: =-Premissas!$C$44*Premissas!I15 -> -1545.15 | K37: =-Premissas!$C$44*Premissas!J15 -> -1485.35 | ... O37: =-Premissas!$C$44*Premissas!N15 -> -1412.9 | P37: =SUM(C37:O37) -> -17588.15 | Q37: =IF(P37=0,0,AVERAGE(C37:O37)) -> -1352.9346
B38: ='Plano de Contas'!B38 -> Outras despesas variáveis | C38: =-Premissas!$C$45*Premissas!C15 -> 0 | D38: =-Premissas!$C$45*Premissas!D15 -> 0 | E38: =-Premissas!$C$45*Premissas!E15 -> 0 | F38: =-Premissas!$C$45*Premissas!F15 -> 0 | G38: =-Premissas!$C$45*Premissas!G15 -> 0 | H38: =-Premissas!$C$45*Premissas!H15 -> 0 | I38: =-Premissas!$C$45*Premissas!I15 -> 0 | J38: =-Premissas!$C$45*Premissas!J15 -> 0 | ... O38: =-Premissas!$C$45*Premissas!O15 -> 0 | P38: =SUM(C38:O38) -> 0 | Q38: =IF(P38=0,0,AVERAGE(C38:O38)) -> 0
B39: ='Plano de Contas'!B39 -> ENTRADA FL. INVESTIMENTO | C39: =SUM(C40:C41) -> 0 | D39: =SUM(D40:D41) -> 0 | E39: =SUM(E40:E41) -> 0 | F39: =SUM(F40:F41) -> 0 | G39: =SUM(G40:G41) -> 0 | H39: =SUM(H40:H41) -> 0 | I39: =SUM(I40:I41) -> 0 | J39: =SUM(J40:J41) -> 0 | ... O39: =SUM(O40:O41) -> 0 | P39: =SUM(C39:O39) -> 0 | Q39: =IF(P39=0,0,AVERAGE(C39:O39)) -> 0
B40: ='Plano de Contas'!B40 -> Resgate Aplicações Financeiras | P40: =SUM(C40:O40) -> 0 | Q40: =IF(P40=0,0,AVERAGE(C40:O40)) -> 0
B41: ='Plano de Contas'!B41 -> Venda Ativo | P41: =SUM(C41:O41) -> 0 | Q41: =IF(P41=0,0,AVERAGE(C41:O41)) -> 0
B42: ='Plano de Contas'!B42 -> SAÍDA FL. INVESTIMENTO | C42: =SUM(C43:C45) -> 0 | D42: =SUM(D43:D45) -> 0 | E42: =SUM(E43:E45) -> 0 | F42: =SUM(F43:F45) -> 0 | G42: =SUM(G43:G45) -> 0 | H42: =SUM(H43:H45) -> 0 | I42: =SUM(I43:I45) -> 0 | J42: =SUM(J43:J45) -> 0 | ... O42: =SUM(O43:O45) -> 0 | P42: =SUM(C42:O42) -> 0 | Q42: =IF(P42=0,0,AVERAGE(C42:O42)) -> 0
B43: ='Plano de Contas'!B43 -> Aplicação financeira | P43: =SUM(C43:O43) -> 0 | Q43: =IF(P43=0,0,AVERAGE(C43:O43)) -> 0
B44: ='Plano de Contas'!B44 -> Ativo imobilizado | P44: =SUM(C44:O44) -> 0 | Q44: =IF(P44=0,0,AVERAGE(C44:O44)) -> 0
B45: ='Plano de Contas'!B45 -> Treinamento | P45: =SUM(C45:O45) -> 0 | Q45: =IF(P45=0,0,AVERAGE(C45:O45)) -> 0
B46: ='Plano de Contas'!B46 -> ENTRADA FL. FINANCIAMENTO | C46: =SUM(C47:C48) -> 939.6 | D46: =SUM(D47:D48) -> 0 | E46: =SUM(E47:E48) -> 0 | F46: =SUM(F47:F48) -> 0 | G46: =SUM(G47:G48) -> 0 | H46: =SUM(H47:H48) -> 0 | I46: =SUM(I47:I48) -> 0 | J46: =SUM(J47:J48) -> 0 | ... O46: =SUM(O47:O48) -> 0 | P46: =SUM(C46:O46) -> 939.6 | Q46: =IF(P46=0,0,AVERAGE(C46:O46)) -> 72.276923
B47: ='Plano de Contas'!B47 -> Aporte Sócios | P47: =SUM(C47:O47) -> 0 | Q47: =IF(P47=0,0,AVERAGE(C47:O47)) -> 0
B48: ='Plano de Contas'!B48 -> Recebimento de Empréstimo | C48: =IF(SUM(C54,C64,C65,C49)<0,-1*SUM(C54,C64,C65,C49),0) -> 939.6 | D48: =IF(SUM(D54,D64,D65,D49)<0,-1*SUM(D54,D64,D65,D49),0) -> 0 | E48: =IF(SUM(E54,E64,E65,E49)<0,-1*SUM(E54,E64,E65,E49),0) -> 0 | F48: =IF(SUM(F54,F64,F65,F49)<0,-1*SUM(F54,F64,F65,F49),0) -> 0 | G48: =IF(SUM(G54,G64,G65,G49)<0,-1*SUM(G54,G64,G65,G49),0) -> 0 | H48: =IF(SUM(H54,H64,H65,H49)<0,-1*SUM(H54,H64,H65,H49),0) -> 0 | I48: =IF(SUM(I54,I64,I65,I49)<0,-1*SUM(I54,I64,I65,I49),0) -> 0 | J48: =IF(SUM(J54,J64,J65,J49)<0,-1*SUM(J54,J64,J65,J49),0) -> 0 | ... N48: =IF(SUM(N54,N64,N65,N49)<0,-1*SUM(N54,N64,N65,N49),0) -> 0 | P48: =SUM(C48:O48) -> 939.6 | Q48: =IF(P48=0,0,AVERAGE(C48:O48)) -> 78.3
B49: ='Plano de Contas'!B49 -> SAÍDA FL. FINANCIAMENTO | C49: =SUM(C50:C52) -> 0 | D49: =SUM(D50:D52) -> -5432.0904 | E49: =SUM(E50:E52) -> -4589.3833 | F49: =SUM(F50:F52) -> -4981.6382 | G49: =SUM(G50:G52) -> -4851.865 | H49: =SUM(H50:H52) -> -4912.3116 | I49: =SUM(I50:I52) -> -4878.3543 | J49: =SUM(J50:J52) -> -4990.376 | ... O49: =SUM(O50:O52) -> -142.38744 | P49: =SUM(C49:O49) -> -53839.013 | Q49: =IF(P49=0,0,AVERAGE(C49:O49)) -> -4141.4625
B50: ='Plano de Contas'!B50 -> Distribuição de Lucros | C50: =IF(C66>0,-40%*C66,0) -> 0 | D50: =IF(D66>0,-40%*D66,0) -> -4473.6984 | E50: =IF(E66>0,-40%*E66,0) -> -4589.3833 | F50: =IF(F66>0,-40%*F66,0) -> -4981.6382 | G50: =IF(G66>0,-40%*G66,0) -> -4851.865 | H50: =IF(H66>0,-40%*H66,0) -> -4912.3116 | I50: =IF(I66>0,-40%*I66,0) -> -4878.3543 | J50: =IF(J66>0,-40%*J66,0) -> -4990.376 | ... O50: =IF(O66>0,-40%*O66,0) -> -142.38744 | P50: =SUM(C50:O50) -> -52880.621 | Q50: =IF(P50=0,0,AVERAGE(C50:O50)) -> -4067.7401
...

Sheet Fluxo_Diário
A2: ="Fluxo de Caixa Diário - "&Premissas!C4 -> Fluxo de Caixa Diário - 2020
B4: Ref. | C4: Caixa | D4: Entradas | E4: Saídas | F4: Saldo | M4: Entradas | O4: =SUMIF(O$9:O$1048576,">0",O$9:O$1048576) -> 56325 | P4: =SUMIF(P$9:P$1048576,">0",P$9:P$1048576) -> 19889 | Q4: =SUMIF(Q$9:Q$1048576,">0",Q$9:Q$1048576) -> 62947 | R4: =SUMIF(R$9:R$1048576,">0",R$9:R$1048576) -> 31838 | S4: =SUMIF(S$9:S$1048576,">0",S$9:S$1048576) -> 53566 | T4: =SUMIF(T$9:T$1048576,">0",T$9:T$1048576) -> 91372 | U4: =SUMIF(U$9:U$1048576,">0",U$9:U$1048576) -> 77493 | V4: =SUMIF(V$9:V$1048576,">0",V$9:V$1048576) -> 0 | ... Z4: =SUMIF(Z$9:Z$1048576,">0",Z$9:Z$1048576) -> 0
B5: Jan | C5: Previsão | D5: =SUMIFS(E$9:E$1048576,E$9:E$1048576,">0",A$9:A$1048576,B5) -> 7500 | E5: =SUMIFS(E$9:E$1048576,E$9:E$1048576,"<0",A$9:A$1048576,B5) -> -2575 | F5: =SUM(D5:E5) -> 4925 | M5: Saídas | O5: =SUMIF(O$9:O$1048576,"<0",O$9:O$1048576) -> -17533 | P5: =SUMIF(P$9:P$1048576,"<0",P$9:P$1048576) -> -18498 | Q5: =SUMIF(Q$9:Q$1048576,"<0",Q$9:Q$1048576) -> -13538 | R5: =SUMIF(R$9:R$1048576,"<0",R$9:R$1048576) -> -18686 | S5: =SUMIF(S$9:S$1048576,"<0",S$9:S$1048576) -> -14023 | T5: =SUMIF(T$9:T$1048576,"<0",T$9:T$1048576) -> -9541 | U5: =SUMIF(U$9:U$1048576,"<0",U$9:U$1048576) -> -6506 | V5: =SUMIF(V$9:V$1048576,"<0",V$9:V$1048576) -> -1355 | ... Z5: =SUMIF(Z$9:Z$1048576,"<0",Z$9:Z$1048576) -> 0
B6: =TODAY() -> 44037 | C6: Efetivo | D6: =SUMIFS(Fluxo_Diário_DB!G:G,Fluxo_Diário_DB!G:G,">0",Fluxo_Diário_DB!F:F,"<="&B6) -> 378827 | E6: =SUMIFS(Fluxo_Diário_DB!G:G,Fluxo_Diário_DB!G:G,"<0",Fluxo_Diário_DB!F:F,"<="&B6) -> -93143 | F6: =SUM(D6:E6) -> 285684 | M6: Saldo | O6: =SUM(O4:O5) -> 38792 | P6: =SUM(P4:P5) -> 1391 | Q6: =SUM(Q4:Q5) -> 49409 | R6: =SUM(R4:R5) -> 13152 | S6: =SUM(S4:S5) -> 39543 | T6: =SUM(T4:T5) -> 81831 | U6: =SUM(U4:U5) -> 70987 | V6: =SUM(V4:V5) -> -1355 | ... Z6: =SUM(Z4:Z5) -> 0
G7: Saída | H7: Entrada | O7: 1 | P7: 2 | Q7: 3 | R7: 4 | S7: 5 | T7: 6 | U7: 7 | V7: 8 | W7: 9 | X7: 10 | Y7: 11 | Z7: 12
B8: Data de Reg. | C8: Valor | D8: Data Efet. | E8: Valor | F8: Doc. Pgto. | G8: Nº Doc | H8: Doc. Fiscal | I8: Categoria | J8: Histórico | L8: Saldo Prev. | M8: Saldo Real. | O8: Jan | P8: Fev | Q8: Mar | R8: Abr | S8: Mai | T8: Jun | U8: Jul | V8: Ago | W8: Set | X8: Out | Y8: Nov | Z8: Dez
A9: =IF(D9="","",TEXT(D9,"mmm")) -> dez | B9: 43830 | C9: 0 | D9: 43830 | E9: 0 | J9: Saldo Inicial | L9: =C9 -> 0 | M9: =E9 -> 0
A10: =IF(D10="","",TEXT(D10,"mmm")) -> jan | B10: 43833 | C10: 1200 | D10: 43834 | E10: 1200 | F10: Deposito bancário | H10: 905006 | I10: Consultoria | J10: Cliente ABC | L10: =C10+L9 -> 1200 | M10: =E10+M9 -> 1200 | O10: =IF($D10="","",IF(MONTH($D10)=O$7,$E10,0)) -> 1200 | P10: =IF($D10="","",IF(MONTH($D10)=P$7,$E10,0)) -> 0 | Q10: =IF($D10="","",IF(MONTH($D10)=Q$7,$E10,0)) -> 0 | R10: =IF($D10="","",IF(MONTH($D10)=R$7,$E10,0)) -> 0 | S10: =IF($D10="","",IF(MONTH($D10)=S$7,$E10,0)) -> 0 | T10: =IF($D10="","",IF(MONTH($D10)=T$7,$E10,0)) -> 0 | U10: =IF($D10="","",IF(MONTH($D10)=U$7,$E10,0)) -> 0 | V10: =IF($D10="","",IF(MONTH($D10)=V$7,$E10,0)) -> 0 | ... Z10: =IF($D10="","",IF(MONTH($D10)=Z$7,$E10,0)) -> 0
A11: =IF(D11="","",TEXT(D11,"mmm")) -> jan | B11: 43833 | C11: -50 | D11: 43833 | E11: -50 | F11: Cobrança bancária | G11: 5455512 | I11: Manutenção prédio | J11: Serviço de Manutenção Predial | L11: =C11+L10 -> 1150 | M11: =E11+M10 -> 1150 | O11: =IF($D11="","",IF(MONTH($D11)=O$7,$E11,0)) -> -50 | P11: =IF($D11="","",IF(MONTH($D11)=P$7,$E11,0)) -> 0 | Q11: =IF($D11="","",IF(MONTH($D11)=Q$7,$E11,0)) -> 0 | R11: =IF($D11="","",IF(MONTH($D11)=R$7,$E11,0)) -> 0 | S11: =IF($D11="","",IF(MONTH($D11)=S$7,$E11,0)) -> 0 | T11: =IF($D11="","",IF(MONTH($D11)=T$7,$E11,0)) -> 0 | U11: =IF($D11="","",IF(MONTH($D11)=U$7,$E11,0)) -> 0 | V11: =IF($D11="","",IF(MONTH($D11)=V$7,$E11,0)) -> 0 | ... Z11: =IF($D11="","",IF(MONTH($D11)=Z$7,$E11,0)) -> 0
A12: =IF(D12="","",TEXT(D12,"mmm")) -> jan | B12: 43834 | C12: -20 | D12: 43834 | E12: -20 | F12: Dinheiro | G12: 5645645 | I12: Cartório | J12: Reconhecimento de Firma | L12: =C12+L11 -> 1130 | M12: =E12+M11 -> 1130 | O12: =IF($D12="","",IF(MONTH($D12)=O$7,$E12,0)) -> -20 | P12: =IF($D12="","",IF(MONTH($D12)=P$7,$E12,0)) -> 0 | Q12: =IF($D12="","",IF(MONTH($D12)=Q$7,$E12,0)) -> 0 | R12: =IF($D12="","",IF(MONTH($D12)=R$7,$E12,0)) -> 0 | S12: =IF($D12="","",IF(MONTH($D12)=S$7,$E12,0)) -> 0 | T12: =IF($D12="","",IF(MONTH($D12)=T$7,$E12,0)) -> 0 | U12: =IF($D12="","",IF(MONTH($D12)=U$7,$E12,0)) -> 0 | V12: =IF($D12="","",IF(MONTH($D12)=V$7,$E12,0)) -> 0 | ... Z12: =IF($D12="","",IF(MONTH($D12)=Z$7,$E12,0)) -> 0
A13: =IF(D13="","",TEXT(D13,"mmm")) -> jan | B13: 43835 | C13: 500 | D13: 43840 | E13: 500 | F13: Deposito bancário | H13: 403518 | I13: Licença de software | J13: Cliente XYZ | L13: =C13+L12 -> 1630 | M13: =E13+M12 -> 1630 | O13: =IF($D13="","",IF(MONTH($D13)=O$7,$E13,0)) -> 500 | P13: =IF($D13="","",IF(MONTH($D13)=P$7,$E13,0)) -> 0 | Q13: =IF($D13="","",IF(MONTH($D13)=Q$7,$E13,0)) -> 0 | R13: =IF($D13="","",IF(MONTH($D13)=R$7,$E13,0)) -> 0 | S13: =IF($D13="","",IF(MONTH($D13)=S$7,$E13,0)) -> 0 | T13: =IF($D13="","",IF(MONTH($D13)=T$7,$E13,0)) -> 0 | U13: =IF($D13="","",IF(MONTH($D13)=U$7,$E13,0)) -> 0 | V13: =IF($D13="","",IF(MONTH($D13)=V$7,$E13,0)) -> 0 | ... Z13: =IF($D13="","",IF(MONTH($D13)=Z$7,$E13,0)) -> 0
A14: =IF(D14="","",TEXT(D14,"mmm")) -> jan | B14: 43835 | C14: 800 | D14: 43840 | E14: 800 | F14: Deposito bancário | H14: 868641 | I14: Manutenção de Sistemas | J14: Cliente XYZ | L14: =C14+L13 -> 2430 | M14: =E14+M13 -> 2430 | O14: =IF($D14="","",IF(MONTH($D14)=O$7,$E14,0)) -> 800 | P14: =IF($D14="","",IF(MONTH($D14)=P$7,$E14,0)) -> 0 | Q14: =IF($D14="","",IF(MONTH($D14)=Q$7,$E14,0)) -> 0 | R14: =IF($D14="","",IF(MONTH($D14)=R$7,$E14,0)) -> 0 | S14: =IF($D14="","",IF(MONTH($D14)=S$7,$E14,0)) -> 0 | T14: =IF($D14="","",IF(MONTH($D14)=T$7,$E14,0)) -> 0 | U14: =IF($D14="","",IF(MONTH($D14)=U$7,$E14,0)) -> 0 | V14: =IF($D14="","",IF(MONTH($D14)=V$7,$E14,0)) -> 0 | ... Z14: =IF($D14="","",IF(MONTH($D14)=Z$7,$E14,0)) -> 0
A15: =IF(D15="","",TEXT(D15,"mmm")) -> jan | B15: 43835 | C15: 5000 | D15: 43840 | E15: 5000 | F15: Deposito bancário | H15: 615347 | I15: Consultoria | J15: Cliente XYZ | L15: =C15+L14 -> 7430 | M15: =E15+M14 -> 7430 | O15: =IF($D15="","",IF(MONTH($D15)=O$7,$E15,0)) -> 5000 | P15: =IF($D15="","",IF(MONTH($D15)=P$7,$E15,0)) -> 0 | Q15: =IF($D15="","",IF(MONTH($D15)=Q$7,$E15,0)) -> 0 | R15: =IF($D15="","",IF(MONTH($D15)=R$7,$E15,0)) -> 0 | S15: =IF($D15="","",IF(MONTH($D15)=S$7,$E15,0)) -> 0 | T15: =IF($D15="","",IF(MONTH($D15)=T$7,$E15,0)) -> 0 | U15: =IF($D15="","",IF(MONTH($D15)=U$7,$E15,0)) -> 0 | V15: =IF($D15="","",IF(MONTH($D15)=V$7,$E15,0)) -> 0 | ... Z15: =IF($D15="","",IF(MONTH($D15)=Z$7,$E15,0)) -> 0
A16: =IF(D16="","",TEXT(D16,"mmm")) -> jan | B16: 43837 | C16: -30 | D16: 43837 | E16: -30 | F16: Deposito bancário | G16: 5455512 | I16: Material escritório | J16: Resma | L16: =C16+L15 -> 7400 | M16: =E16+M15 -> 7400 | O16: =IF($D16="","",IF(MONTH($D16)=O$7,$E16,0)) -> -30 | P16: =IF($D16="","",IF(MONTH($D16)=P$7,$E16,0)) -> 0 | Q16: =IF($D16="","",IF(MONTH($D16)=Q$7,$E16,0)) -> 0 | R16: =IF($D16="","",IF(MONTH($D16)=R$7,$E16,0)) -> 0 | S16: =IF($D16="","",IF(MONTH($D16)=S$7,$E16,0)) -> 0 | T16: =IF($D16="","",IF(MONTH($D16)=T$7,$E16,0)) -> 0 | U16: =IF($D16="","",IF(MONTH($D16)=U$7,$E16,0)) -> 0 | V16: =IF($D16="","",IF(MONTH($D16)=V$7,$E16,0)) -> 0 | ... Z16: =IF($D16="","",IF(MONTH($D16)=Z$7,$E16,0)) -> 0
A17: =IF(D17="","",TEXT(D17,"mmm")) -> jan | B17: 43837 | C17: -100 | D17: 43837 | E17: -100 | F17: Deposito bancário | G17: 5645645 | I17: Água | J17: Água do estacionamento | L17: =C17+L16 -> 7300 | M17: =E17+M16 -> 7300 | O17: =IF($D17="","",IF(MONTH($D17)=O$7,$E17,0)) -> -100 | P17: =IF($D17="","",IF(MONTH($D17)=P$7,$E17,0)) -> 0 | Q17: =IF($D17="","",IF(MONTH($D17)=Q$7,$E17,0)) -> 0 | R17: =IF($D17="","",IF(MONTH($D17)=R$7,$E17,0)) -> 0 | S17: =IF($D17="","",IF(MONTH($D17)=S$7,$E17,0)) -> 0 | T17: =IF($D17="","",IF(MONTH($D17)=T$7,$E17,0)) -> 0 | U17: =IF($D17="","",IF(MONTH($D17)=U$7,$E17,0)) -> 0 | V17: =IF($D17="","",IF(MONTH($D17)=V$7,$E17,0)) -> 0 | ... Z17: =IF($D17="","",IF(MONTH($D17)=Z$7,$E17,0)) -> 0
A18: =IF(D18="","",TEXT(D18,"mmm")) -> jan | B18: 43837 | C18: -45 | D18: 43837 | E18: -45 | F18: Deposito bancário | G18: 5835778 | I18: Correios | J18: Envio de Sedex | L18: =C18+L17 -> 7255 | M18: =E18+M17 -> 7255 | O18: =IF($D18="","",IF(MONTH($D18)=O$7,$E18,0)) -> -45 | P18: =IF($D18="","",IF(MONTH($D18)=P$7,$E18,0)) -> 0 | Q18: =IF($D18="","",IF(MONTH($D18)=Q$7,$E18,0)) -> 0 | R18: =IF($D18="","",IF(MONTH($D18)=R$7,$E18,0)) -> 0 | S18: =IF($D18="","",IF(MONTH($D18)=S$7,$E18,0)) -> 0 | T18: =IF($D18="","",IF(MONTH($D18)=T$7,$E18,0)) -> 0 | U18: =IF($D18="","",IF(MONTH($D18)=U$7,$E18,0)) -> 0 | V18: =IF($D18="","",IF(MONTH($D18)=V$7,$E18,0)) -> 0 | ... Z18: =IF($D18="","",IF(MONTH($D18)=Z$7,$E18,0)) -> 0
A19: =IF(D19="","",TEXT(D19,"mmm")) -> jan | B19: 43837 | C19: -500 | D19: 43837 | E19: -500 | F19: Deposito bancário | G19: 6025911 | I19: Material limpeza | J19: Complementar | L19: =C19+L18 -> 6755 | M19: =E19+M18 -> 6755 | O19: =IF($D19="","",IF(MONTH($D19)=O$7,$E19,0)) -> -500 | P19: =IF($D19="","",IF(MONTH($D19)=P$7,$E19,0)) -> 0 | Q19: =IF($D19="","",IF(MONTH($D19)=Q$7,$E19,0)) -> 0 | R19: =IF($D19="","",IF(MONTH($D19)=R$7,$E19,0)) -> 0 | S19: =IF($D19="","",IF(MONTH($D19)=S$7,$E19,0)) -> 0 | T19: =IF($D19="","",IF(MONTH($D19)=T$7,$E19,0)) -> 0 | U19: =IF($D19="","",IF(MONTH($D19)=U$7,$E19,0)) -> 0 | V19: =IF($D19="","",IF(MONTH($D19)=V$7,$E19,0)) -> 0 | ... Z19: =IF($D19="","",IF(MONTH($D19)=Z$7,$E19,0)) -> 0
A20: =IF(D20="","",TEXT(D20,"mmm")) -> jan | B20: 43837 | C20: -1000 | D20: 43837 | E20: -1000 | F20: Deposito bancário | G20: 6216044 | I20: Manutenção equipamentos | J20: Manutenção na impressora | L20: =C20+L19 -> 5755 | M20: =E20+M19 -> 5755 | O20: =IF($D20="","",IF(MONTH($D20)=O$7,$E20,0)) -> -1000 | P20: =IF($D20="","",IF(MONTH($D20)=P$7,$E20,0)) -> 0 | Q20: =IF($D20="","",IF(MONTH($D20)=Q$7,$E20,0)) -> 0 | R20: =IF($D20="","",IF(MONTH($D20)=R$7,$E20,0)) -> 0 | S20: =IF($D20="","",IF(MONTH($D20)=S$7,$E20,0)) -> 0 | T20: =IF($D20="","",IF(MONTH($D20)=T$7,$E20,0)) -> 0 | U20: =IF($D20="","",IF(MONTH($D20)=U$7,$E20,0)) -> 0 | V20: =IF($D20="","",IF(MONTH($D20)=V$7,$E20,0)) -> 0 | ... Z20: =IF($D20="","",IF(MONTH($D20)=Z$7,$E20,0)) -> 0
A21: =IF(D21="","",TEXT(D21,"mmm")) -> jan | B21: 43837 | C21: -800 | D21: 43837 | E21: -800 | F21: Deposito bancário | G21: 6406177 | I21: Terceirizados | J21: Encanador | L21: =C21+L20 -> 4955 | M21: =E21+M20 -> 4955 | O21: =IF($D21="","",IF(MONTH($D21)=O$7,$E21,0)) -> -800 | P21: =IF($D21="","",IF(MONTH($D21)=P$7,$E21,0)) -> 0 | Q21: =IF($D21="","",IF(MONTH($D21)=Q$7,$E21,0)) -> 0 | R21: =IF($D21="","",IF(MONTH($D21)=R$7,$E21,0)) -> 0 | S21: =IF($D21="","",IF(MONTH($D21)=S$7,$E21,0)) -> 0 | T21: =IF($D21="","",IF(MONTH($D21)=T$7,$E21,0)) -> 0 | U21: =IF($D21="","",IF(MONTH($D21)=U$7,$E21,0)) -> 0 | V21: =IF($D21="","",IF(MONTH($D21)=V$7,$E21,0)) -> 0 | ... Z21: =IF($D21="","",IF(MONTH($D21)=Z$7,$E21,0)) -> 0
A22: =IF(D22="","",TEXT(D22,"mmm")) -> jan | B22: 43837 | C22: -10 | D22: 43837 | E22: -10 | F22: Dinheiro | G22: 6596310 | I22: Correios | J22: Envio de Sedex | L22: =C22+L21 -> 4945 | M22: =E22+M21 -> 4945 | O22: =IF($D22="","",IF(MONTH($D22)=O$7,$E22,0)) -> -10 | P22: =IF($D22="","",IF(MONTH($D22)=P$7,$E22,0)) -> 0 | Q22: =IF($D22="","",IF(MONTH($D22)=Q$7,$E22,0)) -> 0 | R22: =IF($D22="","",IF(MONTH($D22)=R$7,$E22,0)) -> 0 | S22: =IF($D22="","",IF(MONTH($D22)=S$7,$E22,0)) -> 0 | T22: =IF($D22="","",IF(MONTH($D22)=T$7,$E22,0)) -> 0 | U22: =IF($D22="","",IF(MONTH($D22)=U$7,$E22,0)) -> 0 | V22: =IF($D22="","",IF(MONTH($D22)=V$7,$E22,0)) -> 0 | ... Z22: =IF($D22="","",IF(MONTH($D22)=Z$7,$E22,0)) -> 0
A23: =IF(D23="","",TEXT(D23,"mmm")) -> jan | B23: 43837 | C23: -10 | D23: 43837 | E23: -10 | F23: Dinheiro | G23: 6786443 | I23: Correios | J23: Envio de Sedex | L23: =C23+L22 -> 4935 | M23: =E23+M22 -> 4935 | O23: =IF($D23="","",IF(MONTH($D23)=O$7,$E23,0)) -> -10 | P23: =IF($D23="","",IF(MONTH($D23)=P$7,$E23,0)) -> 0 | Q23: =IF($D23="","",IF(MONTH($D23)=Q$7,$E23,0)) -> 0 | R23: =IF($D23="","",IF(MONTH($D23)=R$7,$E23,0)) -> 0 | S23: =IF($D23="","",IF(MONTH($D23)=S$7,$E23,0)) -> 0 | T23: =IF($D23="","",IF(MONTH($D23)=T$7,$E23,0)) -> 0 | U23: =IF($D23="","",IF(MONTH($D23)=U$7,$E23,0)) -> 0 | V23: =IF($D23="","",IF(MONTH($D23)=V$7,$E23,0)) -> 0 | ... Z23: =IF($D23="","",IF(MONTH($D23)=Z$7,$E23,0)) -> 0
A24: =IF(D24="","",TEXT(D24,"mmm")) -> jan | B24: 43837 | C24: -10 | D24: 43837 | E24: -10 | F24: Dinheiro | G24: 6976576 | I24: Correios | J24: Envio de Sedex | L24: =C24+L23 -> 4925 | M24: =E24+M23 -> 4925 | O24: =IF($D24="","",IF(MONTH($D24)=O$7,$E24,0)) -> -10 | P24: =IF($D24="","",IF(MONTH($D24)=P$7,$E24,0)) -> 0 | Q24: =IF($D24="","",IF(MONTH($D24)=Q$7,$E24,0)) -> 0 | R24: =IF($D24="","",IF(MONTH($D24)=R$7,$E24,0)) -> 0 | S24: =IF($D24="","",IF(MONTH($D24)=S$7,$E24,0)) -> 0 | T24: =IF($D24="","",IF(MONTH($D24)=T$7,$E24,0)) -> 0 | U24: =IF($D24="","",IF(MONTH($D24)=U$7,$E24,0)) -> 0 | V24: =IF($D24="","",IF(MONTH($D24)=V$7,$E24,0)) -> 0 | ... Z24: =IF($D24="","",IF(MONTH($D24)=Z$7,$E24,0)) -> 0
A25: =IF(D25="","",TEXT(D25,"mmm")) -> fev | B25: 43838 | C25: -4000 | D25: 43871 | E25: -4000 | F25: Deposito bancário | G25: 6976576 | I25: Segurança | J25: Segurança Predial | L25: =C25+L24 -> 925 | M25: =E25+M24 -> 925 | O25: =IF($D25="","",IF(MONTH($D25)=O$7,$E25,0)) -> 0 | P25: =IF($D25="","",IF(MONTH($D25)=P$7,$E25,0)) -> -4000 | Q25: =IF($D25="","",IF(MONTH($D25)=Q$7,$E25,0)) -> 0 | R25: =IF($D25="","",IF(MONTH($D25)=R$7,$E25,0)) -> 0 | S25: =IF($D25="","",IF(MONTH($D25)=S$7,$E25,0)) -> 0 | T25: =IF($D25="","",IF(MONTH($D25)=T$7,$E25,0)) -> 0 | U25: =IF($D25="","",IF(MONTH($D25)=U$7,$E25,0)) -> 0 | V25: =IF($D25="","",IF(MONTH($D25)=V$7,$E25,0)) -> 0 | ... Z25: =IF($D25="","",IF(MONTH($D25)=Z$7,$E25,0)) -> 0
A26: =IF(D26="","",TEXT(D26,"mmm")) -> fev | B26: 43838 | C26: 3500 | D26: 43876 | E26: 3500 | F26: Cobrança bancária | H26: 753492 | I26: Consultoria | J26: Cliente ABC | L26: =C26+L25 -> 4425 | M26: =E26+M25 -> 4425 | O26: =IF($D26="","",IF(MONTH($D26)=O$7,$E26,0)) -> 0 | P26: =IF($D26="","",IF(MONTH($D26)=P$7,$E26,0)) -> 3500 | Q26: =IF($D26="","",IF(MONTH($D26)=Q$7,$E26,0)) -> 0 | R26: =IF($D26="","",IF(MONTH($D26)=R$7,$E26,0)) -> 0 | S26: =IF($D26="","",IF(MONTH($D26)=S$7,$E26,0)) -> 0 | T26: =IF($D26="","",IF(MONTH($D26)=T$7,$E26,0)) -> 0 | U26: =IF($D26="","",IF(MONTH($D26)=U$7,$E26,0)) -> 0 | V26: =IF($D26="","",IF(MONTH($D26)=V$7,$E26,0)) -> 0 | ... Z26: =IF($D26="","",IF(MONTH($D26)=Z$7,$E26,0)) -> 0
B27: =B26+2 -> 43840 | C27: -2209 | D27: 43841 | E27: -2209 | F27: Cobrança bancária | G27: 5455512 | I27: Correios | L27: =C27+L26 -> 2216 | M27: =E27+M26 -> 2216 | O27: =IF($D27="","",IF(MONTH($D27)=O$7,$E27,0)) -> -2209 | P27: =IF($D27="","",IF(MONTH($D27)=P$7,$E27,0)) -> 0 | Q27: =IF($D27="","",IF(MONTH($D27)=Q$7,$E27,0)) -> 0 | R27: =IF($D27="","",IF(MONTH($D27)=R$7,$E27,0)) -> 0 | S27: =IF($D27="","",IF(MONTH($D27)=S$7,$E27,0)) -> 0 | T27: =IF($D27="","",IF(MONTH($D27)=T$7,$E27,0)) -> 0 | U27: =IF($D27="","",IF(MONTH($D27)=U$7,$E27,0)) -> 0 | V27: =IF($D27="","",IF(MONTH($D27)=V$7,$E27,0)) -> 0 | ... Z27: =IF($D27="","",IF(MONTH($D27)=Z$7,$E27,0)) -> 0
B28: =B27+2 -> 43842 | C28: -2713 | D28: 43845 | E28: -2713 | F28: Dinheiro | G28: 5645645 | I28: Impostos municipais | L28: =C28+L27 -> -497 | M28: =E28+M27 -> -497 | O28: =IF($D28="","",IF(MONTH($D28)=O$7,$E28,0)) -> -2713 | P28: =IF($D28="","",IF(MONTH($D28)=P$7,$E28,0)) -> 0 | Q28: =IF($D28="","",IF(MONTH($D28)=Q$7,$E28,0)) -> 0 | R28: =IF($D28="","",IF(MONTH($D28)=R$7,$E28,0)) -> 0 | S28: =IF($D28="","",IF(MONTH($D28)=S$7,$E28,0)) -> 0 | T28: =IF($D28="","",IF(MONTH($D28)=T$7,$E28,0)) -> 0 | U28: =IF($D28="","",IF(MONTH($D28)=U$7,$E28,0)) -> 0 | V28: =IF($D28="","",IF(MONTH($D28)=V$7,$E28,0)) -> 0 | ... Z28: =IF($D28="","",IF(MONTH($D28)=Z$7,$E28,0)) -> 0
B29: =B28+2 -> 43844 | C29: -2946 | D29: 43845 | E29: -2946 | F29: Deposito bancário | G29: 5455512 | I29: Energia | L29: =C29+L28 -> -3443 | M29: =E29+M28 -> -3443 | O29: =IF($D29="","",IF(MONTH($D29)=O$7,$E29,0)) -> -2946 | P29: =IF($D29="","",IF(MONTH($D29)=P$7,$E29,0)) -> 0 | Q29: =IF($D29="","",IF(MONTH($D29)=Q$7,$E29,0)) -> 0 | R29: =IF($D29="","",IF(MONTH($D29)=R$7,$E29,0)) -> 0 | S29: =IF($D29="","",IF(MONTH($D29)=S$7,$E29,0)) -> 0 | T29: =IF($D29="","",IF(MONTH($D29)=T$7,$E29,0)) -> 0 | U29: =IF($D29="","",IF(MONTH($D29)=U$7,$E29,0)) -> 0 | V29: =IF($D29="","",IF(MONTH($D29)=V$7,$E29,0)) -> 0 | ... Z29: =IF($D29="","",IF(MONTH($D29)=Z$7,$E29,0)) -> 0
B30: =B29+2 -> 43846 | C30: -3164 | D30: 43849 | E30: -3164 | F30: Deposito bancário | G30: 5645645 | I30: Fones / Comunicação | L30: =C30+L29 -> -6607 | M30: =E30+M29 -> -6607 | O30: =IF($D30="","",IF(MONTH($D30)=O$7,$E30,0)) -> -3164 | P30: =IF($D30="","",IF(MONTH($D30)=P$7,$E30,0)) -> 0 | Q30: =IF($D30="","",IF(MONTH($D30)=Q$7,$E30,0)) -> 0 | R30: =IF($D30="","",IF(MONTH($D30)=R$7,$E30,0)) -> 0 | S30: =IF($D30="","",IF(MONTH($D30)=S$7,$E30,0)) -> 0 | T30: =IF($D30="","",IF(MONTH($D30)=T$7,$E30,0)) -> 0 | U30: =IF($D30="","",IF(MONTH($D30)=U$7,$E30,0)) -> 0 | V30: =IF($D30="","",IF(MONTH($D30)=V$7,$E30,0)) -> 0 | ... Z30: =IF($D30="","",IF(MONTH($D30)=Z$7,$E30,0)) -> 0
B31: =B30+2 -> 43848 | C31: -2037 | D31: 43849 | E31: -2037 | F31: Deposito bancário | G31: 5835778 | I31: Impostos/taxas diversas | L31: =C31+L30 -> -8644 | M31: =E31+M30 -> -8644 | O31: =IF($D31="","",IF(MONTH($D31)=O$7,$E31,0)) -> -2037 | P31: =IF($D31="","",IF(MONTH($D31)=P$7,$E31,0)) -> 0 | Q31: =IF($D31="","",IF(MONTH($D31)=Q$7,$E31,0)) -> 0 | R31: =IF($D31="","",IF(MONTH($D31)=R$7,$E31,0)) -> 0 | S31: =IF($D31="","",IF(MONTH($D31)=S$7,$E31,0)) -> 0 | T31: =IF($D31="","",IF(MONTH($D31)=T$7,$E31,0)) -> 0 | U31: =IF($D31="","",IF(MONTH($D31)=U$7,$E31,0)) -> 0 | V31: =IF($D31="","",IF(MONTH($D31)=V$7,$E31,0)) -> 0 | ... Z31: =IF($D31="","",IF(MONTH($D31)=Z$7,$E31,0)) -> 0
B32: =B31+2 -> 43850 | C32: 14762 | D32: 43853 | E32: 14762 | F32: Deposito bancário | H32: 446501 | I32: Consultoria | J32: Cliente ABC | L32: =C32+L31 -> 6118 | M32: =E32+M31 -> 6118 | O32: =IF($D32="","",IF(MONTH($D32)=O$7,$E32,0)) -> 14762 | P32: =IF($D32="","",IF(MONTH($D32)=P$7,$E32,0)) -> 0 | Q32: =IF($D32="","",IF(MONTH($D32)=Q$7,$E32,0)) -> 0 | R32: =IF($D32="","",IF(MONTH($D32)=R$7,$E32,0)) -> 0 | S32: =IF($D32="","",IF(MONTH($D32)=S$7,$E32,0)) -> 0 | T32: =IF($D32="","",IF(MONTH($D32)=T$7,$E32,0)) -> 0 | U32: =IF($D32="","",IF(MONTH($D32)=U$7,$E32,0)) -> 0 | V32: =IF($D32="","",IF(MONTH($D32)=V$7,$E32,0)) -> 0 | ... Z32: =IF($D32="","",IF(MONTH($D32)=Z$7,$E32,0)) -> 0
B33: =B32+2 -> 43852 | C33: 11949 | D33: 43853 | E33: 11949 | F33: Deposito bancário | H33: 436442 | I33: Licença de software | J33: Cliente XYZ | L33: =C33+L32 -> 18067 | M33: =E33+M32 -> 18067 | O33: =IF($D33="","",IF(MONTH($D33)=O$7,$E33,0)) -> 11949 | P33: =IF($D33="","",IF(MONTH($D33)=P$7,$E33,0)) -> 0 | Q33: =IF($D33="","",IF(MONTH($D33)=Q$7,$E33,0)) -> 0 | R33: =IF($D33="","",IF(MONTH($D33)=R$7,$E33,0)) -> 0 | S33: =IF($D33="","",IF(MONTH($D33)=S$7,$E33,0)) -> 0 | T33: =IF($D33="","",IF(MONTH($D33)=T$7,$E33,0)) -> 0 | U33: =IF($D33="","",IF(MONTH($D33)=U$7,$E33,0)) -> 0 | V33: =IF($D33="","",IF(MONTH($D33)=V$7,$E33,0)) -> 0 | ... Z33: =IF($D33="","",IF(MONTH($D33)=Z$7,$E33,0)) -> 0
B34: =B33+2 -> 43854 | C34: 14655 | D34: 43857 | E34: 14655 | F34: Dinheiro | H34: 526689 | I34: Manutenção de Sistemas | J34: Cliente XYZ | L34: =C34+L33 -> 32722 | M34: =E34+M33 -> 32722 | O34: =IF($D34="","",IF(MONTH($D34)=O$7,$E34,0)) -> 14655 | P34: =IF($D34="","",IF(MONTH($D34)=P$7,$E34,0)) -> 0 | Q34: =IF($D34="","",IF(MONTH($D34)=Q$7,$E34,0)) -> 0 | R34: =IF($D34="","",IF(MONTH($D34)=R$7,$E34,0)) -> 0 | S34: =IF($D34="","",IF(MONTH($D34)=S$7,$E34,0)) -> 0 | T34: =IF($D34="","",IF(MONTH($D34)=T$7,$E34,0)) -> 0 | U34: =IF($D34="","",IF(MONTH($D34)=U$7,$E34,0)) -> 0 | V34: =IF($D34="","",IF(MONTH($D34)=V$7,$E34,0)) -> 0 | ... Z34: =IF($D34="","",IF(MONTH($D34)=Z$7,$E34,0)) -> 0
B35: =B34+2 -> 43856 | C35: 7459 | D35: 43858 | E35: 7459 | F35: Dinheiro | H35: 718362 | I35: Consultoria | J35: Cliente ABC | L35: =C35+L34 -> 40181 | M35: =E35+M34 -> 40181 | O35: =IF($D35="","",IF(MONTH($D35)=O$7,$E35,0)) -> 7459 | P35: =IF($D35="","",IF(MONTH($D35)=P$7,$E35,0)) -> 0 | Q35: =IF($D35="","",IF(MONTH($D35)=Q$7,$E35,0)) -> 0 | R35: =IF($D35="","",IF(MONTH($D35)=R$7,$E35,0)) -> 0 | S35: =IF($D35="","",IF(MONTH($D35)=S$7,$E35,0)) -> 0 | T35: =IF($D35="","",IF(MONTH($D35)=T$7,$E35,0)) -> 0 | U35: =IF($D35="","",IF(MONTH($D35)=U$7,$E35,0)) -> 0 | V35: =IF($D35="","",IF(MONTH($D35)=V$7,$E35,0)) -> 0 | ... Z35: =IF($D35="","",IF(MONTH($D35)=Z$7,$E35,0)) -> 0
B36: =B35+2 -> 43858 | C36: -1889 | D36: 43861 | E36: -1889 | F36: Cartão de crédito | G36: 5835778 | I36: Energia | L36: =C36+L35 -> 38292 | M36: =E36+M35 -> 38292 | O36: =IF($D36="","",IF(MONTH($D36)=O$7,$E36,0)) -> -1889 | P36: =IF($D36="","",IF(MONTH($D36)=P$7,$E36,0)) -> 0 | Q36: =IF($D36="","",IF(MONTH($D36)=Q$7,$E36,0)) -> 0 | R36: =IF($D36="","",IF(MONTH($D36)=R$7,$E36,0)) -> 0 | S36: =IF($D36="","",IF(MONTH($D36)=S$7,$E36,0)) -> 0 | T36: =IF($D36="","",IF(MONTH($D36)=T$7,$E36,0)) -> 0 | U36: =IF($D36="","",IF(MONTH($D36)=U$7,$E36,0)) -> 0 | V36: =IF($D36="","",IF(MONTH($D36)=V$7,$E36,0)) -> 0 | ... Z36: =IF($D36="","",IF(MONTH($D36)=Z$7,$E36,0)) -> 0
B37: =B36+2 -> 43860 | C37: -3004 | D37: 43862 | E37: -3004 | F37: Cobrança bancária | G37: 5911831.2 | I37: Impostos federais | L37: =C37+L36 -> 35288 | M37: =E37+M36 -> 35288 | O37: =IF($D37="","",IF(MONTH($D37)=O$7,$E37,0)) -> 0 | P37: =IF($D37="","",IF(MONTH($D37)=P$7,$E37,0)) -> -3004 | Q37: =IF($D37="","",IF(MONTH($D37)=Q$7,$E37,0)) -> 0 | R37: =IF($D37="","",IF(MONTH($D37)=R$7,$E37,0)) -> 0 | S37: =IF($D37="","",IF(MONTH($D37)=S$7,$E37,0)) -> 0 | T37: =IF($D37="","",IF(MONTH($D37)=T$7,$E37,0)) -> 0 | U37: =IF($D37="","",IF(MONTH($D37)=U$7,$E37,0)) -> 0 | V37: =IF($D37="","",IF(MONTH($D37)=V$7,$E37,0)) -> 0 | ... Z37: =IF($D37="","",IF(MONTH($D37)=Z$7,$E37,0)) -> 0
B38: =B37+2 -> 43862 | C38: -1619 | D38: 43863 | E38: -1619 | F38: Cheque | G38: 5987884.4 | I38: Terceirizados | L38: =C38+L37 -> 33669 | M38: =E38+M37 -> 33669 | O38: =IF($D38="","",IF(MONTH($D38)=O$7,$E38,0)) -> 0 | P38: =IF($D38="","",IF(MONTH($D38)=P$7,$E38,0)) -> -1619 | Q38: =IF($D38="","",IF(MONTH($D38)=Q$7,$E38,0)) -> 0 | R38: =IF($D38="","",IF(MONTH($D38)=R$7,$E38,0)) -> 0 | S38: =IF($D38="","",IF(MONTH($D38)=S$7,$E38,0)) -> 0 | T38: =IF($D38="","",IF(MONTH($D38)=T$7,$E38,0)) -> 0 | U38: =IF($D38="","",IF(MONTH($D38)=U$7,$E38,0)) -> 0 | V38: =IF($D38="","",IF(MONTH($D38)=V$7,$E38,0)) -> 0 | ... Z38: =IF($D38="","",IF(MONTH($D38)=Z$7,$E38,0)) -> 0
B39: =B38+2 -> 43864 | C39: -2306 | D39: 43866 | E39: -2306 | F39: Deposito bancário | G39: 6063937.6 | I39: Comissões | L39: =C39+L38 -> 31363 | M39: =E39+M38 -> 31363 | O39: =IF($D39="","",IF(MONTH($D39)=O$7,$E39,0)) -> 0 | P39: =IF($D39="","",IF(MONTH($D39)=P$7,$E39,0)) -> -2306 | Q39: =IF($D39="","",IF(MONTH($D39)=Q$7,$E39,0)) -> 0 | R39: =IF($D39="","",IF(MONTH($D39)=R$7,$E39,0)) -> 0 | S39: =IF($D39="","",IF(MONTH($D39)=S$7,$E39,0)) -> 0 | T39: =IF($D39="","",IF(MONTH($D39)=T$7,$E39,0)) -> 0 | U39: =IF($D39="","",IF(MONTH($D39)=U$7,$E39,0)) -> 0 | V39: =IF($D39="","",IF(MONTH($D39)=V$7,$E39,0)) -> 0 | ... Z39: =IF($D39="","",IF(MONTH($D39)=Z$7,$E39,0)) -> 0
B40: =B39+2 -> 43866 | C40: -474 | D40: 43868 | E40: -474 | F40: Dinheiro | G40: 6139990.8 | I40: Correios | L40: =C40+L39 -> 30889 | M40: =E40+M39 -> 30889 | O40: =IF($D40="","",IF(MONTH($D40)=O$7,$E40,0)) -> 0 | P40: =IF($D40="","",IF(MONTH($D40)=P$7,$E40,0)) -> -474 | Q40: =IF($D40="","",IF(MONTH($D40)=Q$7,$E40,0)) -> 0 | R40: =IF($D40="","",IF(MONTH($D40)=R$7,$E40,0)) -> 0 | S40: =IF($D40="","",IF(MONTH($D40)=S$7,$E40,0)) -> 0 | T40: =IF($D40="","",IF(MONTH($D40)=T$7,$E40,0)) -> 0 | U40: =IF($D40="","",IF(MONTH($D40)=U$7,$E40,0)) -> 0 | V40: =IF($D40="","",IF(MONTH($D40)=V$7,$E40,0)) -> 0 | ... Z40: =IF($D40="","",IF(MONTH($D40)=Z$7,$E40,0)) -> 0
B41: =B40+2 -> 43868 | C41: -50 | D41: 43870 | E41: -50 | F41: Cartão de crédito | G41: 6216044 | I41: Correios | L41: =C41+L40 -> 30839 | M41: =E41+M40 -> 30839 | O41: =IF($D41="","",IF(MONTH($D41)=O$7,$E41,0)) -> 0 | P41: =IF($D41="","",IF(MONTH($D41)=P$7,$E41,0)) -> -50 | Q41: =IF($D41="","",IF(MONTH($D41)=Q$7,$E41,0)) -> 0 | R41: =IF($D41="","",IF(MONTH($D41)=R$7,$E41,0)) -> 0 | S41: =IF($D41="","",IF(MONTH($D41)=S$7,$E41,0)) -> 0 | T41: =IF($D41="","",IF(MONTH($D41)=T$7,$E41,0)) -> 0 | U41: =IF($D41="","",IF(MONTH($D41)=U$7,$E41,0)) -> 0 | V41: =IF($D41="","",IF(MONTH($D41)=V$7,$E41,0)) -> 0 | ... Z41: =IF($D41="","",IF(MONTH($D41)=Z$7,$E41,0)) -> 0
B42: =B41+2 -> 43870 | C42: -1106 | D42: 43872 | E42: -1106 | F42: Cobrança bancária | G42: 6292097.2 | I42: Segurança | L42: =C42+L41 -> 29733 | M42: =E42+M41 -> 29733 | O42: =IF($D42="","",IF(MONTH($D42)=O$7,$E42,0)) -> 0 | P42: =IF($D42="","",IF(MONTH($D42)=P$7,$E42,0)) -> -1106 | Q42: =IF($D42="","",IF(MONTH($D42)=Q$7,$E42,0)) -> 0 | R42: =IF($D42="","",IF(MONTH($D42)=R$7,$E42,0)) -> 0 | S42: =IF($D42="","",IF(MONTH($D42)=S$7,$E42,0)) -> 0 | T42: =IF($D42="","",IF(MONTH($D42)=T$7,$E42,0)) -> 0 | U42: =IF($D42="","",IF(MONTH($D42)=U$7,$E42,0)) -> 0 | V42: =IF($D42="","",IF(MONTH($D42)=V$7,$E42,0)) -> 0 | ... Z42: =IF($D42="","",IF(MONTH($D42)=Z$7,$E42,0)) -> 0
...

Sheet Fluxo_Diário_DB
B2: Data de Reg. | C2: Valor | D2: Acum. | F2: Data Efet. | G2: Valor | H2: Acum. | J2: Real Mil | K2: 1000 | L2: Jan | M2: Fev | N2: Mar | O2: Abr | P2: Mai | Q2: Jun | R2: Jul | S2: Ago | T2: Set | U2: Out | V2: Nov | W2: Dez
B3: =Fluxo_Diário!B9 -> 43830 | C3: =SUMIF(Fluxo_Diário!$B$9:$B$1048576,Fluxo_Diário_DB!B3,Fluxo_Diário!$C$9:$C$1048576) -> 0 | D3: =C3 -> 0 | F3: =B3 -> 43830 | G3: =SUMIF(Fluxo_Diário!$D$9:$D$1048576,Fluxo_Diário_DB!B3,Fluxo_Diário!$E$9:$E$1048576) -> 0 | H3: =G3 -> 0 | J3: Receitas Operacionais | K3: Proj | L3: =Fluxo_Projetado!C55/$K$2 -> 11.68425 | M3: =Fluxo_Projetado!D55/$K$2 -> 28.4895 | N3: =Fluxo_Projetado!E55/$K$2 -> 28.79475 | O3: =Fluxo_Projetado!F55/$K$2 -> 29.8745 | P3: =Fluxo_Projetado!G55/$K$2 -> 29.66875 | Q3: =Fluxo_Projetado!H55/$K$2 -> 29.83025 | R3: =Fluxo_Projetado!I55/$K$2 -> 29.662 | S3: =Fluxo_Projetado!J55/$K$2 -> 30.19775 | ... W3: =Fluxo_Projetado!N55/$K$2 -> 28.70725
B4: =B3+1 -> 43831 | C4: =SUMIF(Fluxo_Diário!$B$9:$B$1048576,Fluxo_Diário_DB!B4,Fluxo_Diário!$C$9:$C$1048576) -> 0 | D4: =C4+D3 -> 0 | F4: =B4 -> 43831 | G4: =SUMIF(Fluxo_Diário!$D$9:$D$1048576,Fluxo_Diário_DB!B4,Fluxo_Diário!$E$9:$E$1048576) -> 0 | H4: =G4+H3 -> 0 | L4: =L3 -> 11.68425 | M4: =M3+L4 -> 40.17375 | N4: =N3+M4 -> 68.9685 | O4: =O3+N4 -> 98.843 | P4: =P3+O4 -> 128.51175 | Q4: =Q3+P4 -> 158.342 | R4: =R3+Q4 -> 188.004 | S4: =S3+R4 -> 218.20175 | T4: =T3+S4 -> 248.31025 | ... W4: =W3+V4 -> 335.6025
B5: =B4+1 -> 43832 | C5: =SUMIF(Fluxo_Diário!$B$9:$B$1048576,Fluxo_Diário_DB!B5,Fluxo_Diário!$C$9:$C$1048576) -> 0 | D5: =C5+D4 -> 0 | F5: =B5 -> 43832 | G5: =SUMIF(Fluxo_Diário!$D$9:$D$1048576,Fluxo_Diário_DB!B5,Fluxo_Diário!$E$9:$E$1048576) -> 0 | H5: =G5+H4 -> 0 | K5: Real | L5: =Fluxo_Realizado!C55/$K$2 -> 56.325 | M5: =Fluxo_Realizado!D55/$K$2 -> 19.889 | N5: =Fluxo_Realizado!E55/$K$2 -> 62.947 | O5: =Fluxo_Realizado!F55/$K$2 -> 31.838 | P5: =Fluxo_Realizado!G55/$K$2 -> 53.566 | Q5: =Fluxo_Realizado!H55/$K$2 -> 91.372 | R5: =Fluxo_Realizado!I55/$K$2 -> 77.493 | S5: =Fluxo_Realizado!J55/$K$2 -> 0 | ... W5: =Fluxo_Realizado!N55/$K$2 -> 0
B6: =B5+1 -> 43833 | C6: =SUMIF(Fluxo_Diário!$B$9:$B$1048576,Fluxo_Diário_DB!B6,Fluxo_Diário!$C$9:$C$1048576) -> 1150 | D6: =C6+D5 -> 1150 | F6: =B6 -> 43833 | G6: =SUMIF(Fluxo_Diário!$D$9:$D$1048576,Fluxo_Diário_DB!B6,Fluxo_Diário!$E$9:$E$1048576) -> -50 | H6: =G6+H5 -> -50 | L6: =L5 -> 56.325 | M6: =M5+L6 -> 76.214 | N6: =N5+M6 -> 139.161 | O6: =O5+N6 -> 170.999 | P6: =P5+O6 -> 224.565 | Q6: =Q5+P6 -> 315.937 | R6: =R5+Q6 -> 393.43 | S6: =S5+R6 -> 393.43 | T6: =T5+S6 -> 393.43 | ... W6: =W5+V6 -> 393.43
B7: =B6+1 -> 43834 | C7: =SUMIF(Fluxo_Diário!$B$9:$B$1048576,Fluxo_Diário_DB!B7,Fluxo_Diário!$C$9:$C$1048576) -> -20 | D7: =C7+D6 -> 1130 | F7: =B7 -> 43834 | G7: =SUMIF(Fluxo_Diário!$D$9:$D$1048576,Fluxo_Diário_DB!B7,Fluxo_Diário!$E$9:$E$1048576) -> 1180 | H7: =G7+H6 -> 1130 | K7: % | L7: =L5/L3 -> 4.8205918 | M7: =M5/M3 -> 0.69811685 | N7: =N5/N3 -> 2.1860582 | O7: =O5/O3 -> 1.0657249 | P7: =P5/P3 -> 1.8054687 | Q7: =Q5/Q3 -> 3.0630652 | R7: =R5/R3 -> 2.6125346 | S7: =S5/S3 -> 0 | ... W7: =W5/W3 -> 0
B8: =B7+1 -> 43835 | C8: =SUMIF(Fluxo_Diário!$B$9:$B$1048576,Fluxo_Diário_DB!B8,Fluxo_Diário!$C$9:$C$1048576) -> 6300 | D8: =C8+D7 -> 7430 | F8: =B8 -> 43835 | G8: =SUMIF(Fluxo_Diário!$D$9:$D$1048576,Fluxo_Diário_DB!B8,Fluxo_Diário!$E$9:$E$1048576) -> 0 | H8: =G8+H7 -> 1130
B9: =B8+1 -> 43836 | C9: =SUMIF(Fluxo_Diário!$B$9:$B$1048576,Fluxo_Diário_DB!B9,Fluxo_Diário!$C$9:$C$1048576) -> 0 | D9: =C9+D8 -> 7430 | F9: =B9 -> 43836 | G9: =SUMIF(Fluxo_Diário!$D$9:$D$1048576,Fluxo_Diário_DB!B9,Fluxo_Diário!$E$9:$E$1048576) -> 0 | H9: =G9+H8 -> 1130 | J9: Despesas Fixas | K9: Proj | L9: =-Fluxo_Projetado!C56/$K$2 -> 11.19 | M9: =-Fluxo_Projetado!D56/$K$2 -> 11.19 | N9: =-Fluxo_Projetado!E56/$K$2 -> 11.19 | O9: =-Fluxo_Projetado!F56/$K$2 -> 11.19 | P9: =-Fluxo_Projetado!G56/$K$2 -> 11.19 | Q9: =-Fluxo_Projetado!H56/$K$2 -> 11.19 | R9: =-Fluxo_Projetado!I56/$K$2 -> 11.19 | S9: =-Fluxo_Projetado!J56/$K$2 -> 11.19 | ... W9: =-Fluxo_Projetado!N56/$K$2 -> 11.19
B10: =B9+1 -> 43837 | C10: =SUMIF(Fluxo_Diário!$B$9:$B$1048576,Fluxo_Diário_DB!B10,Fluxo_Diário!$C$9:$C$1048576) -> -2505 | D10: =C10+D9 -> 4925 | F10: =B10 -> 43837 | G10: =SUMIF(Fluxo_Diário!$D$9:$D$1048576,Fluxo_Diário_DB!B10,Fluxo_Diário!$E$9:$E$1048576) -> -2505 | H10: =G10+H9 -> -1375 | L10: =L9 -> 11.19 | M10: =M9+L10 -> 22.38 | N10: =N9+M10 -> 33.57 | O10: =O9+N10 -> 44.76 | P10: =P9+O10 -> 55.95 | Q10: =Q9+P10 -> 67.14 | R10: =R9+Q10 -> 78.33 | S10: =S9+R10 -> 89.52 | T10: =T9+S10 -> 100.71 | ... W10: =W9+V10 -> 134.28
B11: =B10+1 -> 43838 | C11: =SUMIF(Fluxo_Diário!$B$9:$B$1048576,Fluxo_Diário_DB!B11,Fluxo_Diário!$C$9:$C$1048576) -> -500 | D11: =C11+D10 -> 4425 | F11: =B11 -> 43838 | G11: =SUMIF(Fluxo_Diário!$D$9:$D$1048576,Fluxo_Diário_DB!B11,Fluxo_Diário!$E$9:$E$1048576) -> 0 | H11: =G11+H10 -> -1375 | K11: Real | L11: =-Fluxo_Realizado!C56/$K$2 -> 14.82 | M11: =-Fluxo_Realizado!D56/$K$2 -> 10.767 | N11: =-Fluxo_Realizado!E56/$K$2 -> 11.236 | O11: =-Fluxo_Realizado!F56/$K$2 -> 13.123 | P11: =-Fluxo_Realizado!G56/$K$2 -> 11.17 | Q11: =-Fluxo_Realizado!H56/$K$2 -> 7.145 | R11: =-Fluxo_Realizado!I56/$K$2 -> 6.506 | S11: =-Fluxo_Realizado!J56/$K$2 -> 1.355 | ... W11: =-Fluxo_Realizado!N56/$K$2 -> 0
B12: =B11+1 -> 43839 | C12: =SUMIF(Fluxo_Diário!$B$9:$B$1048576,Fluxo_Diário_DB!B12,Fluxo_Diário!$C$9:$C$1048576) -> 0 | D12: =C12+D11 -> 4425 | F12: =B12 -> 43839 | G12: =SUMIF(Fluxo_Diário!$D$9:$D$1048576,Fluxo_Diário_DB!B12,Fluxo_Diário!$E$9:$E$1048576) -> 0 | H12: =G12+H11 -> -1375 | L12: =L11 -> 14.82 | M12: =M11+L12 -> 25.587 | N12: =N11+M12 -> 36.823 | O12: =O11+N12 -> 49.946 | P12: =P11+O12 -> 61.116 | Q12: =Q11+P12 -> 68.261 | R12: =R11+Q12 -> 74.767 | S12: =S11+R12 -> 76.122 | T12: =T11+S12 -> 76.122 | ... W12: =W11+V12 -> 76.122
B13: =B12+1 -> 43840 | C13: =SUMIF(Fluxo_Diário!$B$9:$B$1048576,Fluxo_Diário_DB!B13,Fluxo_Diário!$C$9:$C$1048576) -> -2209 | D13: =C13+D12 -> 2216 | F13: =B13 -> 43840 | G13: =SUMIF(Fluxo_Diário!$D$9:$D$1048576,Fluxo_Diário_DB!B13,Fluxo_Diário!$E$9:$E$1048576) -> 6300 | H13: =G13+H12 -> 4925 | K13: % | L13: =L11/L9 -> 1.3243968 | M13: =M11/M9 -> 0.96219839 | N13: =N11/N9 -> 1.0041108 | O13: =O11/O9 -> 1.1727435 | P13: =P11/P9 -> 0.99821269 | Q13: =Q11/Q9 -> 0.63851653 | R13: =R11/R9 -> 0.58141197 | S13: =S11/S9 -> 0.12109026 | ... W13: =W11/W9 -> 0
B14: =B13+1 -> 43841 | C14: =SUMIF(Fluxo_Diário!$B$9:$B$1048576,Fluxo_Diário_DB!B14,Fluxo_Diário!$C$9:$C$1048576) -> 0 | D14: =C14+D13 -> 2216 | F14: =B14 -> 43841 | G14: =SUMIF(Fluxo_Diário!$D$9:$D$1048576,Fluxo_Diário_DB!B14,Fluxo_Diário!$E$9:$E$1048576) -> -2209 | H14: =G14+H13 -> 2716
B15: =B14+1 -> 43842 | C15: =SUMIF(Fluxo_Diário!$B$9:$B$1048576,Fluxo_Diário_DB!B15,Fluxo_Diário!$C$9:$C$1048576) -> -2713 | D15: =C15+D14 -> -497 | F15: =B15 -> 43842 | G15: =SUMIF(Fluxo_Diário!$D$9:$D$1048576,Fluxo_Diário_DB!B15,Fluxo_Diário!$E$9:$E$1048576) -> 0 | H15: =G15+H14 -> 2716 | J15: Despesas Variáveis | K15: Proj | L15: =-Fluxo_Projetado!C57/$K$2 -> 1.43385 | M15: =-Fluxo_Projetado!D57/$K$2 -> 6.1152541 | N15: =-Fluxo_Projetado!E57/$K$2 -> 6.1312918 | O15: =-Fluxo_Projetado!F57/$K$2 -> 6.2304044 | P15: =-Fluxo_Projetado!G57/$K$2 -> 6.3490876 | Q15: =-Fluxo_Projetado!H57/$K$2 -> 6.3594709 | R15: =-Fluxo_Projetado!I57/$K$2 -> 6.2761143 | S15: =-Fluxo_Projetado!J57/$K$2 -> 6.5318099 | ... W15: =-Fluxo_Projetado!N57/$K$2 -> 6.1495798
B16: =B15+1 -> 43843 | C16: =SUMIF(Fluxo_Diário!$B$9:$B$1048576,Fluxo_Diário_DB!B16,Fluxo_Diário!$C$9:$C$1048576) -> 0 | D16: =C16+D15 -> -497 | F16: =B16 -> 43843 | G16: =SUMIF(Fluxo_Diário!$D$9:$D$1048576,Fluxo_Diário_DB!B16,Fluxo_Diário!$E$9:$E$1048576) -> 0 | H16: =G16+H15 -> 2716 | L16: =L15 -> 1.43385 | M16: =M15+L16 -> 7.5491041 | N16: =N15+M16 -> 13.680396 | O16: =O15+N16 -> 19.9108 | P16: =P15+O16 -> 26.259888 | Q16: =Q15+P16 -> 32.619359 | R16: =R15+Q16 -> 38.895473 | S16: =S15+R16 -> 45.427283 | T16: =T15+S16 -> 51.787736 | ... W16: =W15+V16 -> 70.416517
B17: =B16+1 -> 43844 | C17: =SUMIF(Fluxo_Diário!$B$9:$B$1048576,Fluxo_Diário_DB!B17,Fluxo_Diário!$C$9:$C$1048576) -> -2946 | D17: =C17+D16 -> -3443 | F17: =B17 -> 43844 | G17: =SUMIF(Fluxo_Diário!$D$9:$D$1048576,Fluxo_Diário_DB!B17,Fluxo_Diário!$E$9:$E$1048576) -> 0 | H17: =G17+H16 -> 2716 | K17: Real | L17: =-Fluxo_Realizado!C57/$K$2 -> 2.713 | M17: =-Fluxo_Realizado!D57/$K$2 -> 7.731 | N17: =-Fluxo_Realizado!E57/$K$2 -> 2.302 | O17: =-Fluxo_Realizado!F57/$K$2 -> 5.563 | P17: =-Fluxo_Realizado!G57/$K$2 -> 2.853 | Q17: =-Fluxo_Realizado!H57/$K$2 -> 2.396 | R17: =-Fluxo_Realizado!I57/$K$2 -> 0 | S17: =-Fluxo_Realizado!J57/$K$2 -> 0 | ... W17: =-Fluxo_Realizado!N57/$K$2 -> 0
B18: =B17+1 -> 43845 | C18: =SUMIF(Fluxo_Diário!$B$9:$B$1048576,Fluxo_Diário_DB!B18,Fluxo_Diário!$C$9:$C$1048576) -> 0 | D18: =C18+D17 -> -3443 | F18: =B18 -> 43845 | G18: =SUMIF(Fluxo_Diário!$D$9:$D$1048576,Fluxo_Diário_DB!B18,Fluxo_Diário!$E$9:$E$1048576) -> -5659 | H18: =G18+H17 -> -2943 | L18: =L17 -> 2.713 | M18: =M17+L18 -> 10.444 | N18: =N17+M18 -> 12.746 | O18: =O17+N18 -> 18.309 | P18: =P17+O18 -> 21.162 | Q18: =Q17+P18 -> 23.558 | R18: =R17+Q18 -> 23.558 | S18: =S17+R18 -> 23.558 | T18: =T17+S18 -> 23.558 | ... W18: =W17+V18 -> 23.558
B19: =B18+1 -> 43846 | C19: =SUMIF(Fluxo_Diário!$B$9:$B$1048576,Fluxo_Diário_DB!B19,Fluxo_Diário!$C$9:$C$1048576) -> -3164 | D19: =C19+D18 -> -6607 | F19: =B19 -> 43846 | G19: =SUMIF(Fluxo_Diário!$D$9:$D$1048576,Fluxo_Diário_DB!B19,Fluxo_Diário!$E$9:$E$1048576) -> 0 | H19: =G19+H18 -> -2943 | K19: % | L19: =L17/L15 -> 1.8921087 | M19: =M17/M15 -> 1.2642157 | N19: =N17/N15 -> 0.37545106 | O19: =O17/O15 -> 0.89287944 | P19: =P17/P15 -> 0.4493559 | Q19: =Q17/Q15 -> 0.3767609 | R19: =R17/R15 -> 0 | S19: =S17/S15 -> 0 | ... W19: =W17/W15 -> 0
